Workbook

Sheet Лист1
A2: Код | B2: Штрихкод | C2: Продукт | D2: Цена | E2: Шт | F2: Сумма
A3: ФР-77202370 | B3: 7640168938413 | C3: biomed Зуб. Щетка SENSITIVE ULTRA SOFT PINK SALT 1X12X4 | D3: 19090 | E3: 120 | F3: 1809730
A4: ФР-77198768 | B4: 7640168931919 | C4: biomed Зуб. Щетка Щетина с Вулканическими минералами MINERAL HARD 4X12 | D4: 19090 | E4: 60 | F4: 904870
A5: SP-145 | B5: 7640168937157 | C5: biomed Зуб. Щетка Щетина с Древесным Углем 2024 MEDIUM 1+1 Black 1X8 | D5: 26480 | E5: 80 | F5: 1673540
A6: SP-185 | B6: 7640340650393 | C6: biomed Зуб. Щетка WHITE PEARL MEDIUM 1X4X12 | D6: 19090 | E6: 96 | F6: 1447790
A7: ФР-77198803 | B7: 7640168935573 | C7: biomed Зуб. Щетка Щетина с Древесным Углем 2024 MEDIUM 2+1 Step To Green 1X8 | D7: 30070 | E7: 80 | F7: 1900420
A8: ФР-77198769 | B8: 7640168930479 | C8: biomed Зуб. Щетка Щетина с Древесным Углем 2024 MEDIUM 4X12 | D8: 19090 | E8: 96 | F8: 1447790
A9: ФР-77198770 | B9: 7640168930509 | C9: biomed Зуб. Щетка Щетина с Ионами Серебра 2024 MEDIUM 4X12 | D9: 19090 | E9: 72 | F9: 1085840
A10: ФР-77198772 | B10: 7640168931636 | C10: biomed Комплексный Ополаскиватель VITAFRESH 250 мл 1Х24 | D10: 23550 | E10: 10 | F10: 235500
A11: ФР-77198733 | B11: 7640168936457 | C11: BioMio Baby Натуральное Детское Крем Мыло с маслом Ши 90 гр 1X24 | D11: 16420 | E11: 240 | F11: 3152640
A12: SP-141 | B12: 7640168937621 | C12: BioMio Натуральное Мыло ГРАНАТ И БАЗИЛИК 90 гр 1X24 | D12: 12430 | E12: 24 | F12: 253570
A13: ФР-77202196 | B13: 7640168937560 | C13: BioMio Экологичное Мыло БАТТЕР МАНГО 90 гр 1X24 | D13: 12430 | E13: 24 | F13: 253570
A14: SP-159 | B14: 7640168939175 | C14: BioMio Экологичное Мыло БЕРГАМОТ И ЗЕЛЕНЫЙ ЧАЙ 90 гр 1X24 | D14: 12430 | E14: 48 | F14: 507140
... A102: SP-236 | B102: 0 | C102: SPLAT PF Зуб. Щетка WHETINING MEDIUM 1+1 1X12 | D102: 42500 | E102: 60 | F102: 1912500
A103: ИТОГО | E103: 5224 | F103: 132262590

Sheet Лист2
A2: Код | B2: Штрихкод | C2: Продукт | D2: Код | E2: Цена без скидки | F2: Цена со скидкой | G2: кол-во шт | H2: Сумма без скидки | I2: Сумма со скидкой
A3: ФР-77202370 | B3: 7640168938413 | C3: biomed Зуб. Щетка SENSITIVE ULTRA SOFT PINK SALT 1X12X4 | D3: ФР-77202370 | E3: 19090 | F3: 15081.083 | G3: 120 | H3: 2290800 | I3: 1809730
A4: ФР-77198768 | B4: 7640168931919 | C4: biomed Зуб. Щетка Щетина с Вулканическими минералами MINERAL HARD 4X12 | D4: ФР-77198768 | E4: 19090 | F4: 15081.167 | G4: 60 | H4: 1145400 | I4: 904870
A5: SP-145 | B5: 7640168937157 | C5: biomed Зуб. Щетка Щетина с Древесным Углем 2024 MEDIUM 1+1 Black 1X8 | D5: SP-145 | E5: 26480 | F5: 20919.25 | G5: 80 | H5: 2118400 | I5: 1673540
A6: SP-185 | B6: 7640340650393 | C6: biomed Зуб. Щетка WHITE PEARL MEDIUM 1X4X12 | D6: SP-185 | E6: 19090 | F6: 15081.146 | G6: 96 | H6: 1832640 | I6: 1447790
A7: ФР-77198803 | B7: 7640168935573 | C7: biomed Зуб. Щетка Щетина с Древесным Углем 2024 MEDIUM 2+1 Step To Green 1X8 | D7: ФР-77198803 | E7: 30070 | F7: 23755.25 | G7: 80 | H7: 2405600 | I7: 1900420
A8: ФР-77198769 | B8: 7640168930479 | C8: biomed Зуб. Щетка Щетина с Древесным Углем 2024 MEDIUM 4X12 | D8: ФР-77198769 | E8: 19090 | F8: 15081.146 | G8: 96 | H8: 1832640 | I8: 1447790
A9: ФР-77198770 | B9: 7640168930509 | C9: biomed Зуб. Щетка Щетина с Ионами Серебра 2024 MEDIUM 4X12 | D9: ФР-77198770 | E9: 19090 | F9: 15081.111 | G9: 72 | H9: 1374480 | I9: 1085840
A10: ФР-77198772 | B10: 7640168931636 | C10: biomed Комплексный Ополаскиватель VITAFRESH 250 мл 1Х24 | D10: ФР-77198772 | E10: 23550 | F10: 23550 | G10: 10 | H10: 235500 | I10: 235500
A11: ФР-77198733 | B11: 7640168936457 | C11: BioMio Baby Натуральное Детское Крем Мыло с маслом Ши 90 гр 1X24 | D11: ФР-77198733 | E11: 16420 | F11: 13136 | G11: 240 | H11: 3940800 | I11: 3152640
A12: SP-141 | B12: 7640168937621 | C12: BioMio Натуральное Мыло ГРАНАТ И БАЗИЛИК 90 гр 1X24 | D12: SP-141 | E12: 12430 | F12: 10565.417 | G12: 24 | H12: 298320 | I12: 253570
A13: ФР-77202196 | B13: 7640168937560 | C13: BioMio Экологичное Мыло БАТТЕР МАНГО 90 гр 1X24 | D13: ФР-77202196 | E13: 12430 | F13: 10565.417 | G13: 24 | H13: 298320 | I13: 253570
A14: SP-159 | B14: 7640168939175 | C14: BioMio Экологичное Мыло БЕРГАМОТ И ЗЕЛЕНЫЙ ЧАЙ 90 гр 1X24 | D14: SP-159 | E14: 12430 | F14: 10565.417 | G14: 48 | H14: 596640 | I14: 507140
... A92: SP-280 | B92: 7640108935078 | C92: SPLAT JUICY Зуб. Щетка МАГИЯ ЕДИНОРОГА 1Х12 + значок | D92: SP-280 | E92: 27370 | F92: 20527.5 | G92: 60 | H92: 1642200 | I92: 1231650
A93: SP-280 | B93: 7640168935252 | C93: SPLAT JUICY Зуб. Щетка МАГИЯ ЕДИНОРОГА 1Х12 + значок | D93: SP-280
A94: ФР-77203258 | B94: 7640245620231 | C94: SPLAT JUICY Зуб. Щетка МАГИЯ ЕДИНОРОГА Жемчужная (1+1) 1Х12 | D94: ФР-77203258 | E94: 34520 | F94: 25890 | G94: 60 | H94: 2071200 | I94: 1553400
A95: SP-226 | B95: 7640245621412 | C95: SPLAT KIDS Зуб. Щетка с Ионами Серебра для детей от 2 до 6 лет 1Х12 | D95: SP-226 | E95: 30100 | F95: 30100 | G95: 60 | H95: 1806000 | I95: 1806000
A96: SP-275 | B96: 4603014004789 | C96: SPLAT PF Зуб. Паста БИОКАЛЬЦИЙ 40 мл 1X20 new | D96: SP-275 | E96: 13990 | F96: 10492.5 | G96: 20 | H96: 279800 | I96: 209850
A97: SP-276 | B97: 4603014004741 | C97: SPLAT PF Зуб. Паста ЛЕЧЕБНЫЕ ТРАВЫ 40 мл 1X20 new | D97: SP-276 | E97: 13990 | F97: 10492.5 | G97: 20 | H97: 279800 | I97: 209850
A98: SP-277 | B98: 4603014004802 | C98: SPLAT PF Зуб. Паста ОТБЕЛИВАНИЕ ПЛЮС 40 мл 1X20 new | D98: SP-277 | E98: 13990 | F98: 10492.5 | G98: 20 | H98: 279800 | I98: 209850
A99: SP-234 | B99: 4603014013422 | C99: SPLAT PF Зуб. Щетка CLINIC CARE Medium 1+1 1X12 | D99: SP-234 | E99: 48700 | F99: 36525 | G99: 96 | H99: 4675200 | I99: 3506400
A100: ФР-77203255 | B100: 4603014028679 | C100: SPLAT PF Зуб. Щетка CLINIC CARE Soft 1X12 | D100: ФР-77203255 | E100: 38000 | F100: 28500 | G100: 60 | H100: 2280000 | I100: 1710000
A101: SP-229 | B101: 7640245621924 | C101: SPLAT PF Зуб. Щетка STARS СРЕДНЯЯ 1X4X12 | D101: SP-229 | E101: 20630 | F101: 15472.5 | G101: 60 | H101: 1237800 | I101: 928350
A102: SP-237 | B102: 4603014011909 | C102: SPLAT PF Зуб. Щетка ULTRA complete MEDIUM 1+1 1X12 | D102: SP-237 | E102: 42500 | F102: 31875 | G102: 60 | H102: 2550000 | I102: 1912500
A103: SP-236 | B103: 4603014007315 | C103: SPLAT PF Зуб. Щетка WHETINING MEDIUM 1+1 1X12 | D103: SP-236 | E103: 42500 | F103: 31875 | G103: 60 | H103: 2550000 | I103: 1912500
A104: ИТОГО | D104: ИТОГО | G104: 5224 | H104: =SUM(H3:H103) -> 167308500 | I104: 132262590

Sheet Лист3
B2: Код | C2: Штрихкод | D2: Продукт | E2: Цена без скидки | F2: Цена со скидкой | G2: кол-во шт | H2: Сумма без скидки | I2: Сумма со скидкой
B3: SP-219 | C3: 7640340650690 | D3: biomed Healthywhite Зуб. Паста Клубника 65 гр 1Х12 | E3: 33760 | F3: 33760 | G3: 12 | H3: =E3*G3 -> 405120 | I3: =F3*G3 -> 405120
B4: SP-220 | C4: 7640340650713 | D4: biomed Healthywhite Зуб. Паста Лесная Мята 65 гр 1Х12 | E4: 33760 | F4: 33760 | G4: 12 | H4: =E4*G4 -> 405120 | I4: =F4*G4 -> 405120
B5: SP-221 | C5: 7640340650706 | D5: biomed Healthywhite Зуб. Паста Свежий Огурец и Мята 65 гр 1Х12 | E5: 33760 | F5: 33760 | G5: 12 | H5: =E5*G5 -> 405120 | I5: =F5*G5 -> 405120
B6: SP-254 | C6: 7640340651369 | D6: biomed Детская Зуб. Щетка с Ионами Серебра МЯГКАЯ от 2 лет 1X4X12 | E6: 20700 | F6: 15939 | G6: 24 | H6: =E6*G6 -> 496800 | I6: =F6*G6 -> 382536
B7: SP-246 | C7: 7640340651345 | D7: biomed Зуб. Паста МЯТНЫЙ ШТОРМ 100 гр 1Х25 | E7: 24710 | F7: 20756.4 | G7: 25 | H7: =E7*G7 -> 617750 | I7: =F7*G7 -> 518910
B8: SP-232 | C8: 7640168931438 | D8: biomed Зуб. Паста ОТБЕЛИВАНИЕ С КОКОСОМ 100 гр 1Х25 | E8: 24710 | F8: 24710 | G8: 25 | H8: =E8*G8 -> 617750 | I8: =F8*G8 -> 617750
B9: SP-008/1 | C9: 7640168930424 | D9: biomed Зуб. Паста ОТБЕЛИВАНИЕ С УГЛЕМ 100 гр 1Х25 | E9: 24710 | F9: 24710 | G9: 25 | H9: =E9*G9 -> 617750 | I9: =F9*G9 -> 617750
B10: SP-274 | C10: 7640340650423 | D10: biomed Зуб. Щетка MAX HARD 1X4X12 | E10: 25260 | F10: 20965.8 | G10: 24 | H10: =E10*G10 -> 606240 | I10: =F10*G10 -> 503179.2
B11: SP-190 | C11: 7640340650423 | D11: biomed Зуб. Щетка MAX MEDIUM 1X4X12 | E11: 25260 | F11: 20965.8 | G11: 24 | H11: =E11*G11 -> 606240 | I11: =F11*G11 -> 503179.2
B12: SP-273 | C12: =VLOOKUP(B12,[1]Лист1!$B:$C,2,0) -> 7640340650935 | D12: biomed Зуб. Щетка SENSITIVE ULTRA SOFT PINK SALT 1+1 1X8 | E12: 27900 | F12: 22599 | G12: 24 | H12: =E12*G12 -> 669600 | I12: =F12*G12 -> 542376
B13: ФР-77202370 | C13: 7640168938413 | D13: biomed Зуб. Щетка SENSITIVE ULTRA SOFT PINK SALT 1X12X4 | E13: 19930 | F13: 15146.8 | G13: 24 | H13: =E13*G13 -> 478320 | I13: =F13*G13 -> 363523.2
B14: SP-185 | C14: 7640340650393 | D14: biomed Зуб. Щетка WHITE PEARL MEDIUM 1X4X12 | E14: 19930 | F14: 15146.8 | G14: 24 | H14: =E14*G14 -> 478320 | I14: =F14*G14 -> 363523.2
B15: ФР-77198768 | C15: 7640168931919 | D15: biomed Зуб. Щетка Щетина с Вулканическими минералами MINERAL HARD 4X12 | E15: 19930 | F15: 15146.8 | G15: 24 | H15: =E15*G15 -> 478320 | I15: =F15*G15 -> 363523.2
B16: SP-145 | C16: 7640168937157 | D16: biomed Зуб. Щетка Щетина с Древесным Углем 2024 MEDIUM 1+1 Black 1X8 | E16: 27900 | F16: 22599 | G16: 16 | H16: =E16*G16 -> 446400 | I16: =F16*G16 -> 361584
B17: ФР-77198803 | C17: 7640168935573 | D17: biomed Зуб. Щетка Щетина с Древесным Углем 2024 MEDIUM 2+1 Step To Green 1X8 | E17: 31610 | F17: 25604.1 | G17: 16 | H17: =E17*G17 -> 505760 | I17: =F17*G17 -> 409665.6
B18: ФР-77198769 | C18: 7640168930479 | D18: biomed Зуб. Щетка Щетина с Древесным Углем 2024 MEDIUM 4X12 | E18: 19930 | F18: 15146.8 | G18: 24 | H18: =E18*G18 -> 478320 | I18: =F18*G18 -> 363523.2
B19: ФР-77198770 | C19: 7640168930509 | D19: biomed Зуб. Щетка Щетина с Ионами Серебра 2024 MEDIUM 4X12 | E19: 19930 | F19: 15146.8 | G19: 24 | H19: =E19*G19 -> 478320 | I19: =F19*G19 -> 363523.2
B20: SP-214 | C20: 7640340650942 | D20: biomed Зуб. Щетка Щетина с Ионами Серебра MEDIUM 1+1 1X50 | E20: 27900 | F20: 22599 | G20: 24 | H20: =E20*G20 -> 669600 | I20: =F20*G20 -> 542376
B21: ФР-77198772 | C21: 7640168931636 | D21: biomed Комплексный Ополаскиватель VITAFRESH 250 мл 1Х24 | E21: 24710 | F21: 24710 | G21: 4 | H21: =E21*G21 -> 98840 | I21: =F21*G21 -> 98840
B22: ФР-77198733 | C22: 7640168936457 | D22: BioMio Baby Натуральное Детское Крем Мыло с маслом Ши 90 гр 1X24 | E22: 17320 | F22: 13682.8 | G22: 24 | H22: =E22*G22 -> 415680 | I22: =F22*G22 -> 328387.2
B23: SP-200 | C23: 7640245620309 | D23: BioMio Жидкое Мыло С Апельсин Бергамот 300 мл 1X12 | E23: 47170 | F23: 47170 | G23: 12 | H23: =E23*G23 -> 566040 | I23: =F23*G23 -> 566040
B24: SP-198 | C24: 7640245620293 | D24: BioMio Жидкое Мыло С Персик Фрезия 300 мл 1X12 | E24: 47170 | F24: 47170 | G24: 12 | H24: =E24*G24 -> 566040 | I24: =F24*G24 -> 566040
... B37: SP-225 | C37: 4603014028907 | D37: SOLZAO Sugar Head гель-уход для душа с маслом бразильского ореха 400 мл 1Х6 | E37: 60470 | F37: 42329 | G37: 18 | H37: =E37*G37 -> 1088460 | I37: =F37*G37 -> 761922
B38: SP-284 | C38: =VLOOKUP(B38,[1]Лист1!$B:$C,2,0) -> 4603014040114 | D38: SPLAT BABY Зуб. Паста для первых зубов 0+ Нежная Ромашка 35 мл 1Х18 | E38: 34210 | F38: 34210 | G38: 18 | H38: =E38*G38 -> 615780 | I38: =F38*G38 -> 615780
B39: SP-210 | C39: 7640245621425 | D39: SPLAT BABY Зуб. Щетка с Ионами Серебра для детей от 0 до 3 лет 1Х12 | E39: 31690 | F39: 31690 | G39: 24 | H39: =E39*G39 -> 760560 | I39: =F39*G39 -> 760560
B40: SP-283 | C40: =VLOOKUP(B40,[1]Лист1!$B:$C,2,0) -> 4603014038678 | D40: SPLAT DAILY Зуб. Паста Защита десен 100 гр 1Х25 | E40: 14240 | F40: 14240 | G40: 25 | H40: =E40*G40 -> 356000 | I40: =F40*G40 -> 356000
B41: SP-282 | C41: =VLOOKUP(B41,[1]Лист1!$B:$C,2,0) -> 4603014038685 | D41: SPLAT DAILY Зуб. Паста Суперсвежесть 100 гр 1Х25 | E41: 14240 | F41: 14240 | G41: 25 | H41: =E41*G41 -> 356000 | I41: =F41*G41 -> 356000
B42: SP-281 | C42: =VLOOKUP(B42,[1]Лист1!$B:$C,2,0) -> 4603014038661 | D42: SPLAT DAILY Зуб. Паста Укрепляющее Отбеливание 100 гр 1Х25 | E42: 14240 | F42: 14240 | G42: 25 | H42: =E42*G42 -> 356000 | I42: =F42*G42 -> 356000
B43: SP-270 | C43: 7640245622082 | D43: SPLAT JUICY LAB гель для душа Воздушный Маршмеллоу 400 мл 1Х6 | E43: 47530 | F43: 35647.5 | G43: 12 | H43: =E43*G43 -> 570360 | I43: =F43*G43 -> 427770
B44: SP-271 | C44: 7640245622075 | D44: SPLAT JUICY LAB гель для душа Душистый персик 400 мл 1Х6 | E44: 47530 | F44: 35647.5 | G44: 12 | H44: =E44*G44 -> 570360 | I44: =F44*G44 -> 427770
B45: SP-216 | C45: 7640245620873 | D45: SPLAT JUICY LAB шампунь-кондиционер Спелый Арбуз 250 мл 1Х12 | E45: 47530 | F45: 35647.5 | G45: 12 | H45: =E45*G45 -> 570360 | I45: =F45*G45 -> 427770
B46: SP-180 | C46: 7640168939816 | D46: SPLAT JUICY Зуб. Паста с Гидро-м кальция АРБУЗ 35 мл 1Х20 | E46: 19430 | F46: 13601 | G46: 40 | H46: =E46*G46 -> 777200 | I46: =F46*G46 -> 544040
B47: ФР-77198807 | C47: 4603014004918 | D47: SPLAT JUICY Зуб. Паста с Гидро-м кальция КИВИ-КЛУБНИКА 35 мл 1Х20 | E47: 20360 | F47: 13641.2 | G47: 40 | H47: =E47*G47 -> 814400 | I47: =F47*G47 -> 545648
B48: ФР-77198808 | C48: 4603014004925 | D48: SPLAT JUICY Зуб. Паста с Гидро-м кальция МОРОЖЕНОЕ 35 мл 1Х20 | E48: 20360 | F48: 13641.2 | G48: 40 | H48: =E48*G48 -> 814400 | I48: =F48*G48 -> 545648
B49: SP-181 | C49: 7640168930004 | D49: SPLAT JUICY Зуб. Паста с Гидро-м кальция Сочный ВИНОГРАД 35 мл 1Х20 | E49: 19430 | F49: 13601 | G49: 40 | H49: =E49*G49 -> 777200 | I49: =F49*G49 -> 544040
B50: ФР-77198810 | C50: 4603014004949 | D50: SPLAT JUICY Зуб. Паста с Гидро-м кальция ТУТТИ-ФРУТТИ 35 мл 1Х20 | E50: 20360 | F50: 13641.2 | G50: 40 | H50: =E50*G50 -> 814400 | I50: =F50*G50 -> 545648
B51: SP-201 | C51: 7640245620132 | D51: SPLAT JUICY Зуб. Паста с Солнечной грушей 35 мл 1Х20 | E51: 19430 | F51: 13601 | G51: 40 | H51: =E51*G51 -> 777200 | I51: =F51*G51 -> 544040
B52: ФР-77198811 | C52: 7640168935078 | D52: SPLAT JUICY Зуб. Щетка МАГИЯ ЕДИНОРОГА 1Х12 | E52: 28690 | F52: 21517.5 | G52: 24 | H52: =E52*G52 -> 688560 | I52: =F52*G52 -> 516420
B53: ФР-77203258 | C53: 7640245620231 | D53: SPLAT JUICY Зуб. Щетка МАГИЯ ЕДИНОРОГА Жемчужная (1+1) 1Х12 | E53: 36350 | F53: 29080 | G53: 24 | H53: =E53*G53 -> 872400 | I53: =F53*G53 -> 697920
...
